exceptionman/__init__.py,sha256=e66GwehMNk80pH-ms6LGctT6b8Cp0-32TNLQ8Qu0SG4,147
exceptionman/_traceback.py,sha256=PK1vGVixaeaFsYSqjMSkjTVxZ3Pun7Stm2uKM0Oyidk,25163
exceptionman/hook.py,sha256=hC7fkyXWd7tK7Ni3YZERIzRy9ZfQUBT6Pw7Fy6GIKQ8,3592
exceptionman/reporter_exception.py,sha256=qLAhSgrSzt4GJS_SuvhS1yw78SWkWHCDcQVJem5goTk,608
ExceptionMan-0.0.0.dev55.dist-info/METADATA,sha256=xxc9AANFa3yemOoqGWTeHw_xbIpq0y1IM_BWrViUxyg,169
ExceptionMan-0.0.0.dev55.dist-info/WHEEL,sha256=PZUExdf71Ui_so67QXpySuHtCi3-J3wvF4ORK6k_S8U,91
ExceptionMan-0.0.0.dev55.dist-info/top_level.txt,sha256=RvtuLrPDOpu1qfjaMjO1Zk4yqKcWrvl__X4lbSqGelQ,13
ExceptionMan-0.0.0.dev55.dist-info/RECORD,,
